<?xml version="1.0" encoding="UTF-8"?>
<testng-results ignored="0" total="7" passed="5" failed="2" skipped="0">
  <reporter-output>
  </reporter-output>
  <suite started-at="2020-12-14T11:50:19 CLST" name="Default suite" finished-at="2020-12-14T11:50:19 CLST" duration-ms="96">
    <groups>
    </groups>
    <test started-at="2020-12-14T11:50:19 CLST" name="Default test" finished-at="2020-12-14T11:50:19 CLST" duration-ms="96">
      <class name="Test.AssertUses">
        <test-method signature="TestClaseNotNullFalloInstanciado()[pri:0, instance:Test.AssertUses@7c1e2a9e]" started-at="2020-12-14T11:50:19 CLST" name="TestClaseNotNullFalloInstanciado" finished-at="2020-12-14T11:50:19 CLST" duration-ms="19" status="PASS">
          <reporter-output>
          </reporter-output>
        </test-method> <!-- TestClaseNotNullFalloInstanciado -->
        <test-method signature="TestClaseNullFalloInstanciado()[pri:0, instance:Test.AssertUses@7c1e2a9e]" started-at="2020-12-14T11:50:19 CLST" name="TestClaseNullFalloInstanciado" finished-at="2020-12-14T11:50:19 CLST" duration-ms="3" status="FAIL">
          <exception class="java.lang.AssertionError">
            <message>
              <![CDATA[expected [null] but found [data.Users@5d7148e2]]]>
            </message>
            <full-stacktrace>
              <![CDATA[java.lang.AssertionError: expected [null] but found [data.Users@5d7148e2]
at org.testng.Assert.fail(Assert.java:99)
at org.testng.Assert.failNotSame(Assert.java:1033)
at org.testng.Assert.assertNull(Assert.java:965)
at org.testng.Assert.assertNull(Assert.java:953)
at Test.AssertUses.TestClaseNullFalloInstanciado(AssertUses.java:55)
at java.base/jdk.internal.reflect.NativeMethodAccessorImpl.invoke0(Native Method)
at java.base/jdk.internal.reflect.NativeMethodAccessorImpl.invoke(NativeMethodAccessorImpl.java:62)
at java.base/jdk.internal.reflect.DelegatingMethodAccessorImpl.invoke(DelegatingMethodAccessorImpl.java:43)
at java.base/java.lang.reflect.Method.invoke(Method.java:566)
at org.testng.internal.MethodInvocationHelper.invokeMethod(MethodInvocationHelper.java:132)
at org.testng.internal.TestInvoker.invokeMethod(TestInvoker.java:599)
at org.testng.internal.TestInvoker.invokeTestMethod(TestInvoker.java:174)
at org.testng.internal.MethodRunner.runInSequence(MethodRunner.java:46)
at org.testng.internal.TestInvoker$MethodInvocationAgent.invoke(TestInvoker.java:822)
at org.testng.internal.TestInvoker.invokeTestMethods(TestInvoker.java:147)
at org.testng.internal.TestMethodWorker.invokeTestMethods(TestMethodWorker.java:146)
at org.testng.internal.TestMethodWorker.run(TestMethodWorker.java:128)
at java.base/java.util.ArrayList.forEach(ArrayList.java:1541)
at org.testng.TestRunner.privateRun(TestRunner.java:764)
at org.testng.TestRunner.run(TestRunner.java:585)
at org.testng.SuiteRunner.runTest(SuiteRunner.java:384)
at org.testng.SuiteRunner.runSequentially(SuiteRunner.java:378)
at org.testng.SuiteRunner.privateRun(SuiteRunner.java:337)
at org.testng.SuiteRunner.run(SuiteRunner.java:286)
at org.testng.SuiteRunnerWorker.runSuite(SuiteRunnerWorker.java:53)
at org.testng.SuiteRunnerWorker.run(SuiteRunnerWorker.java:96)
at org.testng.TestNG.runSuitesSequentially(TestNG.java:1218)
at org.testng.TestNG.runSuitesLocally(TestNG.java:1140)
at org.testng.TestNG.runSuites(TestNG.java:1069)
at org.testng.TestNG.run(TestNG.java:1037)
at org.testng.remote.AbstractRemoteTestNG.run(AbstractRemoteTestNG.java:115)
at org.testng.remote.RemoteTestNG.initAndRun(RemoteTestNG.java:251)
at org.testng.remote.RemoteTestNG.main(RemoteTestNG.java:77)
]]>
            </full-stacktrace>
          </exception> <!-- java.lang.AssertionError -->
          <reporter-output>
          </reporter-output>
        </test-method> <!-- TestClaseNullFalloInstanciado -->
        <test-method signature="TestClaseNullOK()[pri:0, instance:Test.AssertUses@7c1e2a9e]" started-at="2020-12-14T11:50:19 CLST" name="TestClaseNullOK" finished-at="2020-12-14T11:50:19 CLST" duration-ms="2" status="PASS">
          <reporter-output>
          </reporter-output>
        </test-method> <!-- TestClaseNullOK -->
        <test-method signature="TestExitoso()[pri:0, instance:Test.AssertUses@7c1e2a9e]" started-at="2020-12-14T11:50:19 CLST" name="TestExitoso" finished-at="2020-12-14T11:50:19 CLST" duration-ms="2" status="PASS">
          <reporter-output>
          </reporter-output>
        </test-method> <!-- TestExitoso -->
        <test-method signature="TestExitosoEquals()[pri:0, instance:Test.AssertUses@7c1e2a9e]" started-at="2020-12-14T11:50:19 CLST" name="TestExitosoEquals" finished-at="2020-12-14T11:50:19 CLST" duration-ms="2" status="PASS">
          <reporter-output>
          </reporter-output>
        </test-method> <!-- TestExitosoEquals -->
        <test-method signature="TestExitosoNotEquals()[pri:0, instance:Test.AssertUses@7c1e2a9e]" started-at="2020-12-14T11:50:19 CLST" name="TestExitosoNotEquals" finished-at="2020-12-14T11:50:19 CLST" duration-ms="1" status="PASS">
          <reporter-output>
          </reporter-output>
        </test-method> <!-- TestExitosoNotEquals -->
        <test-method signature="TestFallo()[pri:0, instance:Test.AssertUses@7c1e2a9e]" started-at="2020-12-14T11:50:19 CLST" name="TestFallo" finished-at="2020-12-14T11:50:19 CLST" duration-ms="2" status="FAIL">
          <exception class="java.lang.AssertionError">
            <message>
              <![CDATA[expected [true] but found [false]]]>
            </message>
            <full-stacktrace>
              <![CDATA[java.lang.AssertionError: expected [true] but found [false]
at org.testng.Assert.fail(Assert.java:99)
at org.testng.Assert.failNotEquals(Assert.java:1037)
at org.testng.Assert.assertTrue(Assert.java:45)
at org.testng.Assert.assertTrue(Assert.java:55)
at Test.AssertUses.TestFallo(AssertUses.java:21)
at java.base/jdk.internal.reflect.NativeMethodAccessorImpl.invoke0(Native Method)
at java.base/jdk.internal.reflect.NativeMethodAccessorImpl.invoke(NativeMethodAccessorImpl.java:62)
at java.base/jdk.internal.reflect.DelegatingMethodAccessorImpl.invoke(DelegatingMethodAccessorImpl.java:43)
at java.base/java.lang.reflect.Method.invoke(Method.java:566)
at org.testng.internal.MethodInvocationHelper.invokeMethod(MethodInvocationHelper.java:132)
at org.testng.internal.TestInvoker.invokeMethod(TestInvoker.java:599)
at org.testng.internal.TestInvoker.invokeTestMethod(TestInvoker.java:174)
at org.testng.internal.MethodRunner.runInSequence(MethodRunner.java:46)
at org.testng.internal.TestInvoker$MethodInvocationAgent.invoke(TestInvoker.java:822)
at org.testng.internal.TestInvoker.invokeTestMethods(TestInvoker.java:147)
at org.testng.internal.TestMethodWorker.invokeTestMethods(TestMethodWorker.java:146)
at org.testng.internal.TestMethodWorker.run(TestMethodWorker.java:128)
at java.base/java.util.ArrayList.forEach(ArrayList.java:1541)
at org.testng.TestRunner.privateRun(TestRunner.java:764)
at org.testng.TestRunner.run(TestRunner.java:585)
at org.testng.SuiteRunner.runTest(SuiteRunner.java:384)
at org.testng.SuiteRunner.runSequentially(SuiteRunner.java:378)
at org.testng.SuiteRunner.privateRun(SuiteRunner.java:337)
at org.testng.SuiteRunner.run(SuiteRunner.java:286)
at org.testng.SuiteRunnerWorker.runSuite(SuiteRunnerWorker.java:53)
at org.testng.SuiteRunnerWorker.run(SuiteRunnerWorker.java:96)
at org.testng.TestNG.runSuitesSequentially(TestNG.java:1218)
at org.testng.TestNG.runSuitesLocally(TestNG.java:1140)
at org.testng.TestNG.runSuites(TestNG.java:1069)
at org.testng.TestNG.run(TestNG.java:1037)
at org.testng.remote.AbstractRemoteTestNG.run(AbstractRemoteTestNG.java:115)
at org.testng.remote.RemoteTestNG.initAndRun(RemoteTestNG.java:251)
at org.testng.remote.RemoteTestNG.main(RemoteTestNG.java:77)
]]>
            </full-stacktrace>
          </exception> <!-- java.lang.AssertionError -->
          <reporter-output>
          </reporter-output>
        </test-method> <!-- TestFallo -->
      </class> <!-- Test.AssertUses -->
    </test> <!-- Default test -->
  </suite> <!-- Default suite -->
</testng-results>
